Workbook

Sheet INFO
A1: HOJA | B1: NOMBRE | C1: CONTENIDO | D1: ¿COMPLETADA? | E1: DESCRIPCIÓN | F1: LEYENDA COLORES | G1: LEYENDA ACRÓNIMOS
A2: Hoja 1 | B2: P_violacea_Spain_Med | C2: Datos generales | D2: SI | E2: Hoja con todos los datos en "bruto" de las ocurrencias de rayas pelágicas. Es importante mantener el formato de todos los datos, para que las otras hojas puedan registrar correctamente los datos | F2: Azul claro (datos de los registros), azul oscuro (anchura disco), naranja (estado encuentro), granate (presencia heridas), verde (sexo individuos), amarillo (edad individuos), rosa (comportamientos observados) | G2: Inds (Número de individuos), nd (no determinado), M (machos), H (hembras), Juv (juveniles), New (recién nacidos), Emb (embriones), DW (anchura de disco), Algo. Int. ("algo interesante"), Posible Emb (embarazo), Agreg (agregaciones), Alimen (alimentación), Rep (repetido). En comportamientos: 0=ausencia; 1=presencia
A3: Hoja 2 | B3: P_violacea_Heridas | C3: Datos heridas | D3: NO | E3: Hoja que recopila datos sobre los individuos que SI y NO tienen heridas, también tiene información y detalles sobre las heridas de los confirmados (conteos según ubicación, estado cicatrices, presencia de simetría etc) | F3: Azul claro (datos de los registros), azul oscuro (anchura disco), naranja (estado encuentro), granate (presencia heridas y características), verde (sexo individuos), amarillo (edad individuos) | G3: Inds (Número de individuos), nd (no determinado), M (machos), H (hembras), Juv (juveniles), New (recién nacidos), Emb (embriones), DW (anchura de disco), Ala_izq (aleta izquierda vista aérea), Ala_drch (aleta derecha vista aérea), Estado_ctrz (cicatriz), Simetría, Obs_heridas (observaciones de las heridas)
A4: Hoja 3 | B4: Conteo_year | C4: Datos anuales | D4: SI | E4: Hoja con contabiliza el número de INDIVIDUOS de forma anual (es automática se actualiza en base a la hoja 1) | F4: Azul (invierno), verde (primavera), rojo (verano), amarillo (otoño)
A5: Hoja 4 | B5: Conteo_region | C5: Datos por regiones | D5: SI | E5: Hoja con contabiliza el número de INDIVIDUOS de según provincias y comunidades autónomas (es automática se actualiza en base a la hoja 1) | F5: Naranja (Cataluña y sus provincias), amarillo (Comunitat Valenciana y sus provincias), violeta (Región de Murcia), verde (Andalucía y sus provincias), azul (Islas Baleares), gris oscuro (Ceuta), gris claro (Melilla), rosa (nd)
A6: Hoja 5 | B6: Conteo_year_regions | C6: Datos anuales y regionales | D6: SI | E6: Hoja automática que recopila individuos a nivel regional y también anual en el Mediterráneo español | F6: Azul (invierno), verde (primavera), rojo (verano), amarillo (otoño); Naranja (Cataluña y sus provincias), amarillo (Comunitat Valenciana y sus provincias), violeta (Región de Murcia), verde (Andalucía y sus provincias), azul (Islas Baleares), gris oscuro (Ceuta), gris claro (Melilla), rosa (nd)
A7: Hoja 6 | B7: nd | C7: Datos comportamientos | D7: NO | E7: Hoja resumen recopilatoria de comportamientos de especial interés que se han observado, especialmente enfocada a indicar si hay un registro fotográfico de dicho comportamiento

Sheet P_violacea_Spain_Med
A1: ID | B1: Fecha | C1: Estación | D1: Hora | E1: Ubicación | F1: Provincia | G1: Com_Autónoma | H1: Lat | I1: Long | J1: Inds | K1: Viva | L1: Muerta | M1: nd | N1: Heridas | O1: M_sex | P1: H_sex | Q1: nd_sex | R1: Adult | S1: Juv | T1: New | U1: Emb | V1: nd | W1: DW | X1: Algo. Int. | Y1: Apareamiento | Z1: Embarazo | AA1: Posible Emb | AB1: Parto | AC1: Agreg | AD1: Descanso | AE1: Estrés | AF1: Alimen | AG1: Otros | AH1: Fuente_tipo | AI1: Fuente | AJ1: Rep | AK1: Link | AL1: Observaciones
A2: P_violacea_041 | B2: 31989 | C2: Verano | D2: nd | E2: Barcelona | F2: Barcelona | G2: Cataluña | H2: 40.9167 | I2: 2.166666 | J2: 1 | K2: 0 | L2: 1 | M2: 0 | N2: nd | O2: 0 | P2: 0 | Q2: 1 | R2: 0 | S2: 0 | T2: 0 | U2: 0 | V2: 1 | W2: nd | X2: 1 | Y2: 0 | Z2: 0 | AA2: 0 | AB2: 0 | AC2: 0 | AD2: 0 | AE2: 0 | AF2: 0 | AG2: 1 | AH2: Database | AI2: GBIF | AL2: Colección ICM y fue capturada
A3: P_violacea_378 | B3: 38586 | C3: Verano | D3: nd | E3: Vilassar de Mar | F3: Barcelona | G3: Cataluña | H3: 41.502488 | I3: 2.3951611 | J3: 1 | K3: 1 | L3: 0 | M3: 0 | N3: nd | O3: 0 | P3: 0 | Q3: 1 | R3: 0 | S3: 0 | T3: 0 | U3: 0 | V3: 1 | W3: nd | X3: 0 | Y3: 0 | Z3: 0 | AA3: 0 | AB3: 0 | AC3: 0 | AD3: 0 | AE3: 0 | AF3: 0 | AG3: 0 | AH3: Com. Pers. | AI3: Jordi Ruiz-Olmo | AK3: Jordi Ruiz-Olmo | AL3: Coords aproximadas
A4: P_violacea_379 | B4: 38925 | C4: Verano | D4: nd | E4: Castelldefels | F4: Barcelona | G4: Cataluña | H4: 41.263685 | I4: 1.9758406 | J4: 1 | K4: 1 | L4: 0 | M4: 0 | N4: nd | O4: 0 | P4: 0 | Q4: 1 | R4: 0 | S4: 0 | T4: 0 | U4: 0 | V4: 1 | W4: nd | X4: 0 | Y4: 0 | Z4: 0 | AA4: 0 | AB4: 0 | AC4: 0 | AD4: 0 | AE4: 0 | AF4: 0 | AG4: 0 | AH4: Com. Pers. | AI4: Jordi Ruiz-Olmo | AK4: Jordi Ruiz-Olmo | AL4: Coords aproximadas
A5: P_violacea_380 | B5: 39325 | C5: Verano | D5: nd | E5: Torredembarra | F5: Tarragona | G5: Cataluña | H5: 41.140554 | I5: 1.4074053 | J5: 1 | K5: 1 | L5: 0 | M5: 0 | N5: nd | O5: 0 | P5: 0 | Q5: 1 | R5: 0 | S5: 0 | T5: 0 | U5: 0 | V5: 1 | W5: nd | X5: 0 | Y5: 0 | Z5: 0 | AA5: 0 | AB5: 0 | AC5: 0 | AD5: 0 | AE5: 0 | AF5: 0 | AG5: 0 | AH5: Com. Pers. | AI5: Jordi Ruiz-Olmo | AK5: Jordi Ruiz-Olmo | AL5: Coords aproximadas
A6: P_violacea_381 | B6: 39327 | C6: Otoño | D6: nd | E6: Creixell | F6: Tarragona | G6: Cataluña | H6: 41.155801 | I6: 1.4417468 | J6: 1 | K6: 1 | L6: 0 | M6: 0 | N6: nd | O6: 0 | P6: 0 | Q6: 1 | R6: 0 | S6: 0 | T6: 0 | U6: 0 | V6: 1 | W6: nd | X6: 0 | Y6: 0 | Z6: 0 | AA6: 0 | AB6: 0 | AC6: 0 | AD6: 0 | AE6: 0 | AF6: 0 | AG6: 0 | AH6: Com. Pers. | AI6: Jordi Ruiz-Olmo | AK6: Jordi Ruiz-Olmo | AL6: Coords aproximadas
A7: P_violacea_382 | B7: 39328 | C7: Otoño | D7: nd | E7: Cubelles | F7: Barcelona | G7: Cataluña | H7: 41.200311 | I7: 1.6798339 | J7: 1 | K7: 1 | L7: 0 | M7: 0 | N7: nd | O7: 0 | P7: 0 | Q7: 1 | R7: 0 | S7: 0 | T7: 0 | U7: 0 | V7: 1 | W7: nd | X7: 0 | Y7: 0 | Z7: 0 | AA7: 0 | AB7: 0 | AC7: 0 | AD7: 0 | AE7: 0 | AF7: 0 | AG7: 0 | AH7: Com. Pers. | AI7: Jordi Ruiz-Olmo | AK7: Jordi Ruiz-Olmo | AL7: Coords aproximadas
A8: P_violacea_383 | B8: 39335 | C8: Otoño | D8: nd | E8: Cubelles | F8: Barcelona | G8: Cataluña | H8: 41.200311 | I8: 1.6798339 | J8: 1 | K8: 1 | L8: 0 | M8: 0 | N8: nd | O8: 0 | P8: 0 | Q8: 1 | R8: 0 | S8: 0 | T8: 0 | U8: 0 | V8: 1 | W8: nd | X8: 0 | Y8: 0 | Z8: 0 | AA8: 0 | AB8: 0 | AC8: 0 | AD8: 0 | AE8: 0 | AF8: 0 | AG8: 0 | AH8: Com. Pers. | AI8: Jordi Ruiz-Olmo | AK8: Jordi Ruiz-Olmo | AL8: Coords aproximadas
A9: P_violacea_014 | B9: 40668 | C9: Primavera | D9: nd | F9: Málaga | G9: Andalucía | H9: 36.3334 | I9: -4.3398 | J9: 1 | K9: 0 | L9: 1 | M9: 0 | N9: nd | O9: 0 | P9: 0 | Q9: 1 | R9: 0 | S9: 0 | T9: 0 | U9: 0 | V9: 1 | W9: nd | X9: 0 | Y9: 0 | Z9: 0 | AA9: 0 | AB9: 0 | AC9: 0 | AD9: 0 | AE9: 0 | AF9: 0 | AG9: 0 | AH9: Database | AI9: GBIF | AL9: Fixed and preserved in alcohol
A10: P_violacea_142 | B10: 40745 | C10: Verano | D10: nd | E10: San Agustín | F10: Almería | G10: Andalucía | H10: 36.672067 | I10: -2.6606359 | J10: 2 | K10: 2 | L10: 0 | M10: 0 | N10: nd | O10: 1 | P10: 1 | Q10: 0 | R10: 2 | S10: 0 | T10: 0 | U10: 0 | V10: 0 | W10: nd | X10: 1 | Y10: 1 | Z10: 0 | AA10: 0 | AB10: 0 | AC10: 0 | AD10: 0 | AE10: 0 | AF10: 0 | AG10: 0 | AH10: Database | AI10: Obsdelmar | AK10: https://www.observadoresdelmar.es/Observations/1800306 | AL10: Apareamiento
A11: P_violacea_194 | B11: 40777 | C11: Verano | D11: nd | E11: Cala de la Media Luna | F11: Almería | G11: Andalucía | H11: 36.730233 | I11: -2.1517176 | J11: 1 | K11: 1 | L11: 0 | M11: 0 | N11: No | O11: 0 | P11: 0 | Q11: 1 | R11: 1 | S11: 0 | T11: 0 | U11: 0 | V11: 0 | W11: nd | X11: 0 | Y11: 0 | Z11: 0 | AA11: 0 | AB11: 0 | AC11: 0 | AD11: 0 | AE11: 0 | AF11: 0 | AG11: 0 | AH11: Redes Sociales | AI11: YouTube | AK11: https://www.youtube.com/watch?v=wCBtYuAlgLc&ab_channel=waljalapensacola
A12: P_violacea_030 | B12: 41136 | C12: Verano | D12: nd | E12: Torrevieja | F12: Alicante | G12: Comunidad Valenciana | H12: 38.006 | I12: -0.6494 | J12: 1 | K12: 1 | L12: 0 | M12: 0 | N12: Si | O12: 0 | P12: 0 | Q12: 1 | R12: 0 | S12: 0 | T12: 1 | U12: 0 | V12: 0 | W12: nd | X12: 1 | Y12: 0 | Z12: 0 | AA12: 0 | AB12: 0 | AC12: 0 | AD12: 0 | AE12: 0 | AF12: 0 | AG12: 1 | AH12: Database | AI12: Obsdelmar | AK12: https://www.observadoresdelmar.es/Observations/213423 | AL12: Es MUY pequeño y gran herida
A13: P_violacea_384 | B13: 41149 | C13: Verano | D13: nd | E13: Castelldefels | F13: Barcelona | G13: Cataluña | H13: 41.263685 | I13: 1.9758406 | J13: 1 | K13: 1 | L13: 0 | M13: 0 | N13: nd | O13: 0 | P13: 0 | Q13: 1 | R13: 0 | S13: 0 | T13: 0 | U13: 0 | V13: 1 | W13: nd | X13: 0 | Y13: 0 | Z13: 0 | AA13: 0 | AB13: 0 | AC13: 0 | AD13: 0 | AE13: 0 | AF13: 0 | AG13: 0 | AH13: Com. Pers. | AI13: Jordi Ruiz-Olmo | AK13: Jordi Ruiz-Olmo | AL13: Coords aproximadas
A14: P_violacea_193 | B14: 41487 | C14: Verano | D14: nd | E14: Platja del Cristall | F14: Barcelona | G14: Cataluña | H14: 41.454693 | I14: 2.2606424 | J14: 1 | K14: 1 | L14: 0 | M14: 0 | N14: nd | O14: 0 | P14: 0 | Q14: 1 | R14: 0 | S14: 0 | T14: 0 | U14: 0 | V14: 1 | W14: nd | X14: 0 | Y14: 0 | Z14: 0 | AA14: 0 | AB14: 0 | AC14: 0 | AD14: 0 | AE14: 0 | AF14: 0 | AG14: 0 | AH14: Redes Sociales | AI14: YouTube | AK14: https://www.youtube.com/watch?v=Mqcgv6MKX8M&ab_channel=Marcel%C2%B7l%C3%ADMiret
A15: P_violacea_042 | B15: 41506 | C15: Verano | D15: nd | E15: Islas Columbretes | F15: Castellón | G15: Comunidad Valenciana | H15: 39.890047 | I15: 0.66895061 | J15: 1 | K15: 1 | L15: 0 | M15: 0 | N15: Si | O15: 0 | P15: 1 | Q15: 0 | R15: 1 | S15: 0 | T15: 0 | U15: 0 | V15: 0 | W15: nd | X15: 1 | Y15: 0 | Z15: 1 | AA15: 0 | AB15: 0 | AC15: 0 | AD15: 0 | AE15: 0 | AF15: 0 | AG15: 0 | AH15: Redes Sociales | AI15: YouTube | AK15: https://www.youtube.com/watch?v=FTKvVXQBYJ8 | AL15: Parece que está embarazada!
A16: P_violacea_012 | B16: 41508 | C16: Verano | D16: nd | E16: Cala Santanyí | F16: Islas Baleares | G16: Islas Baleares | H16: 39.322646 | I16: 3.1462631 | J16: 1 | K16: 0 | L16: 0 | M16: 1 | N16: No | O16: 0 | P16: 1 | Q16: 0 | R16: 1 | S16: 0 | T16: 0 | U16: 0 | V16: 0 | W16: nd | X16: 0 | Y16: 0 | Z16: 0 | AA16: 0 | AB16: 0 | AC16: 0 | AD16: 0 | AE16: 0 | AF16: 0 | AG16: 0 | AH16: Database | AI16: GBIF | AK16: https://observation.org/observation/297108565/
A17: P_violacea_025 | B17: 41509 | C17: Verano | D17: nd | E17: La Mata | F17: Alicante | G17: Comunidad Valenciana | H17: 38.0196 | I17: -0.6518 | J17: 1 | K17: 0 | L17: 1 | M17: 0 | N17: No | O17: 0 | P17: 0 | Q17: 1 | R17: 0 | S17: 1 | T17: 0 | U17: 0 | V17: 0 | W17: nd | X17: 1 | Y17: 0 | Z17: 0 | AA17: 0 | AB17: 0 | AC17: 0 | AD17: 0 | AE17: 0 | AF17: 0 | AG17: 1 | AH17: Database | AI17: Obsdelmar | AK17: https://www.observadoresdelmar.es/Observations/213424 | AL17: Se ve muy pequeño y se puede estimar tamaño
A18: P_violacea_260 | B18: 41516 | C18: Verano | D18: 0.58333333 | E18: La Malva-Rosa | F18: Valencia | G18: Comunidad Valenciana | H18: 39.477407 | I18: -0.32260827 | J18: 3 | K18: 3 | L18: 0 | M18: 0 | N18: nd | O18: 0 | P18: 1 | Q18: 2 | R18: 1 | S18: 0 | T18: 2 | U18: 0 | V18: 0 | W18: nd | X18: 1 | Y18: 0 | Z18: 0 | AA18: 0 | AB18: 1 | AC18: 0 | AD18: 0 | AE18: 0 | AF18: 0 | AG18: 0 | AH18: Prensa | AI18: Levante-EMV | AK18: https://www.levante-emv.com/valencia/2013/08/01/reabren-playas-valencia-verse-ayer-12875744.html | AL18: Las crías nacieron en el Oceanográfic (https://www.levante-emv.com/valencia/2013/08/27/nacen-crias-pez-raya-hallado-12868514.html). Las crías pesan alrededor de 150 gramos, presentan un diámetro de unos 10 centímetros y tienen su aguijón bien formado al principio de su cola de 35 centímetros. También en este vídeo (https://www.youtube.com/watch?v=MzI9cYTy06s&ab_channel=GeneralitatValenciana) mencionan que de 7 rayas pelágicas atentidas ese año (2013), 6 presentaban signos de parto y la otra pues parió ahí en cuarentena etc
A19: P_violacea_261 | B19: 41516 | C19: Verano | D19: 0.58333333 | E19: Playa del Cabanyal | F19: Valencia | G19: Comunidad Valenciana | H19: 39.468527 | I19: -0.32183886 | J19: 2 | K19: 2 | L19: 0 | M19: 0 | N19: nd | O19: 0 | P19: 0 | Q19: 2 | R19: 0 | S19: 0 | T19: 0 | U19: 0 | V19: 2 | W19: nd | X19: 0 | Y19: 0 | Z19: 0 | AA19: 0 | AB19: 0 | AC19: 0 | AD19: 0 | AE19: 0 | AF19: 0 | AG19: 0 | AH19: Prensa | AI19: Levante-EMV | AK19: https://www.levante-emv.com/valencia/2013/08/01/reabren-playas-valencia-verse-ayer-12875744.html
A20: P_violacea_403 | B20: 41842 | C20: Verano | D20: nd | E20: La Granadella | F20: Alicante | G20: Comunidad Valenciana | H20: 38.727971 | I20: 0.19870985 | J20: 1 | K20: 1 | L20: 0 | M20: 0 | N20: Si | O20: 0 | P20: 1 | Q20: 0 | R20: 1 | S20: 0 | T20: 0 | U20: 0 | V20: 0 | W20: nd | X20: 0 | Y20: 0 | Z20: 0 | AA20: 0 | AB20: 0 | AC20: 0 | AD20: 0 | AE20: 0 | AF20: 0 | AG20: 0 | AH20: Redes Sociales | AI20: Instagram | AK20: https://www.instagram.com/reel/C9ue24et6xk | AL20: Coords aproximadas
A21: P_violacea_144 | B21: 42140 | C21: Primavera | D21: nd | E21: San Agustín | F21: Almería | G21: Andalucía | H21: 36.672067 | I21: -2.6606359 | J21: 1 | K21: 1 | L21: 0 | M21: 0 | N21: Si | O21: 0 | P21: 1 | Q21: 0 | R21: 1 | S21: 0 | T21: 0 | U21: 0 | V21: 0 | W21: nd | X21: 1 | Y21: 0 | Z21: 0 | AA21: 1 | AB21: 0 | AC21: 0 | AD21: 0 | AE21: 0 | AF21: 0 | AG21: 0 | AH21: Database | AI21: Obsdelmar | AK21: https://www.observadoresdelmar.es/Observations/1800301 | AL21: Parece que está embarazada!
A22: P_violacea_031 | B22: 42159 | C22: Verano | D22: nd | E22: Torrevieja | F22: Alicante | G22: Comunidad Valenciana | H22: 37.9854 | I22: -0.6054 | J22: 1 | K22: 0 | L22: 1 | M22: 0 | N22: Si | O22: 0 | P22: 0 | Q22: 1 | R22: 1 | S22: 0 | T22: 0 | U22: 0 | V22: 0 | W22: nd | X22: 1 | Y22: 0 | Z22: 0 | AA22: 0 | AB22: 0 | AC22: 0 | AD22: 0 | AE22: 0 | AF22: 0 | AG22: 0 | AH22: Database | AI22: Obsdelmar | AK22: https://marineinfo.org/id/dataset/6526 | AL22: Tamaño estimado 70-80 cm<br /> Peso estimado 20 kg,Hola J. Antonio, muchas gracias por tu observación. Esta es una especie muy interesante, de la cual no hay muchos reportes en estas costas, si puedes enviarme más fotos estaría muy bien, saludos
A23: P_violacea_019 | B23: 42385 | C23: Invierno | D23: 0.86041667 | F23: Islas Baleares | G23: Islas Baleares | H23: 38.632002 | I23: 0.78201 | J23: 1 | K23: 1 | L23: 0 | M23: 0 | N23: No | O23: 0 | P23: 0 | Q23: 1 | R23: 0 | S23: 0 | T23: 0 | U23: 0 | V23: 1 | W23: nd | X23: 1 | Y23: 0 | Z23: 0 | AA23: 0 | AB23: 0 | AC23: 0 | AD23: 0 | AE23: 0 | AF23: 0 | AG23: 0 | AH23: Database | AI23: GBIF
A24: P_violacea_395 | B24: 42385 | C24: Invierno | D24: nd | E24: Calpe | F24: Alicante | G24: Comunidad Valenciana | H24: 38.631685 | I24: 0.07743468 | J24: 1 | K24: 1 | L24: 0 | M24: 0 | N24: No | O24: 0 | P24: 1 | Q24: 0 | R24: 1 | S24: 0 | T24: 0 | U24: 0 | V24: 0 | W24: nd | X24: 1 | Y24: 0 | Z24: 0 | AA24: 0 | AB24: 0 | AC24: 0 | AD24: 1 | AE24: 0 | AF24: 0 | AG24: 0 | AH24: Database | AI24: iNaturalist | AK24: https://www.inaturalist.org/observations/120705686 | AL24: Descansando sobre el fondo
A25: P_violacea_184 | B25: 42506 | C25: Primavera | D25: nd | E25: Palma | F25: Islas Baleares | G25: Islas Baleares | H25: 39.500224 | I25: 2.66087 | J25: 1 | K25: 1 | L25: 0 | M25: 0 | N25: No | O25: 1 | P25: 0 | Q25: 0 | R25: 1 | S25: 0 | T25: 0 | U25: 0 | V25: 0 | W25: nd | X25: 0 | Y25: 0 | Z25: 0 | AA25: 0 | AB25: 0 | AC25: 0 | AD25: 0 | AE25: 0 | AF25: 0 | AG25: 0 | AH25: Redes Sociales | AI25: YouTube | AK25: https://www.youtube.com/watch?v=fv0huisSrTQ&ab_channel=pacov. | AL25: Coords aproximadas
A26: P_violacea_043 | B26: 42573 | C26: Verano | D26: nd | E26: Enix | F26: Almería | G26: Andalucía | H26: 36.817942 | I26: -2.5332835 | J26: 2 | K26: 2 | L26: 0 | M26: 0 | N26: No | O26: 1 | P26: 1 | Q26: 0 | R26: 2 | S26: 0 | T26: 0 | U26: 0 | V26: 0 | W26: nd | X26: 1 | Y26: 1 | Z26: 0 | AA26: 0 | AB26: 0 | AC26: 0 | AD26: 0 | AE26: 0 | AF26: 0 | AG26: 0 | AH26: Redes Sociales | AI26: Vimeo | AK26: https://vimeo.com/175886064 | AL26: Apareamiento
A27: P_violacea_044 | B27: 42581 | C27: Verano | D27: nd | E27: Moraira | F27: Alicante | G27: Comunidad Valenciana | H27: 38.685822 | I27: 0.15444061 | J27: 1 | K27: 1 | L27: 0 | M27: 0 | N27: Si | O27: 0 | P27: 1 | Q27: 0 | R27: 1 | S27: 0 | T27: 0 | U27: 0 | V27: 0 | W27: nd | X27: 1 | Y27: 0 | Z27: 1 | AA27: 0 | AB27: 0 | AC27: 0 | AD27: 0 | AE27: 0 | AF27: 0 | AG27: 0 | AH27: Redes Sociales | AI27: Facebook | AK27: www.facebook.com/L.Elasmogrup/posts/542435975957971 | AL27: Embarazada
A28: P_violacea_045 | B28: 42581 | C28: Verano | D28: nd | E28: Santa Margalida | F28: Islas Baleares | G28: Islas Baleares | H28: 39.776234 | I28: 3.1497189 | J28: 1 | K28: 1 | L28: 0 | M28: 0 | N28: No | O28: 0 | P28: 0 | Q28: 1 | R28: 1 | S28: 0 | T28: 0 | U28: 0 | V28: 0 | W28: nd | X28: 0 | Y28: 0 | Z28: 0 | AA28: 0 | AB28: 0 | AC28: 0 | AD28: 0 | AE28: 0 | AF28: 0 | AG28: 0 | AH28: Redes Sociales | AI28: Twitter | AK28: https://twitter.com/irenina14/status/759349778249572352 | AL28: En playa y fue reorientada
A29: P_violacea_046 | B29: 42587 | C29: Verano | D29: nd | E29: Punta Prima | F29: Islas Baleares | G29: Islas Baleares | H29: 39.812592 | I29: 4.2835301 | J29: 1 | K29: 0 | L29: 0 | M29: 1 | N29: nd | O29: 0 | P29: 0 | Q29: 1 | R29: 0 | S29: 0 | T29: 0 | U29: 0 | V29: 1 | W29: nd | X29: 0 | Y29: 0 | Z29: 0 | AA29: 0 | AB29: 0 | AC29: 0 | AD29: 0 | AE29: 0 | AF29: 0 | AG29: 0 | AH29: Redes Sociales | AI29: Twitter | AK29: https://twitter.com/tomeumir78/status/761594642739716097 | AL29: Página no existe ya
A30: P_violacea_047 | B30: 42590 | C30: Verano | D30: nd | E30: Barcelona | F30: Barcelona | G30: Cataluña | H30: 41.378808 | I30: 2.1949402 | J30: 1 | K30: 1 | L30: 0 | M30: 0 | N30: No | O30: 0 | P30: 1 | Q30: 0 | R30: 1 | S30: 0 | T30: 0 | U30: 0 | V30: 0 | W30: nd | X30: 0 | Y30: 0 | Z30: 0 | AA30: 0 | AB30: 0 | AC30: 0 | AD30: 0 | AE30: 0 | AF30: 0 | AG30: 0 | AH30: Redes Sociales | AI30: Twitter | AK30: https://twitter.com/rtvenoticies/status/762408730164072448
A31: P_violacea_172 | B31: 42592 | C31: Verano | D31: nd | E31: Xàbia | F31: Alicante | G31: Comunidad Valenciana | H31: 38.818372 | I31: 0.17623412 | J31: 1 | K31: 1 | L31: 0 | M31: 0 | N31: Si | O31: 0 | P31: 0 | Q31: 1 | R31: 0 | S31: 0 | T31: 0 | U31: 0 | V31: 1 | W31: nd | X31: 0 | Y31: 0 | Z31: 0 | AA31: 0 | AB31: 0 | AC31: 0 | AD31: 0 | AE31: 0 | AF31: 0 | AG31: 0 | AH31: Redes Sociales | AI31: Facebook | AK31: https://www.facebook.com/watch/?v=989793194453155&rdid=gyZOVCdabON18HiS
A32: P_violacea_028 | B32: 42595 | C32: Verano | D32: nd | E32: Sa Tuna | F32: Girona | G32: Cataluña | H32: 41.9601 | I32: 3.2315 | J32: 1 | K32: 1 | L32: 0 | M32: 0 | N32: Si | O32: 0 | P32: 1 | Q32: 0 | R32: 1 | S32: 0 | T32: 0 | U32: 0 | V32: 0 | W32: nd | X32: 0 | Y32: 0 | Z32: 0 | AA32: 0 | AB32: 0 | AC32: 0 | AD32: 0 | AE32: 0 | AF32: 0 | AG32: 0 | AH32: Database | AI32: Obsdelmar | AK32: https://www.observadoresdelmar.es/Observations/206216 | AL32: Tengo alguna foto más. No estoy al 100% seguro de que sea esta especie,Muchas gracias Juan! He validado la especie en base a las otras fotos que me mandaste. Tu observación ha sido fundamental para poder confirmar la presencia de esta especie en la Costa Brava: este es el principal valor de "Observadores del mar"! Confirmaría que esta especie se ha dejado ver mucho más al norte y mucho más frecuentemente que nunca en aguas litorales del Mediterráneo noroccidental.
A33: P_violacea_040 | B33: 42596 | C33: Verano | D33: 0.90277778 | E33: Islas Columbretes | F33: Castellón | G33: Comunidad Valenciana | H33: 39.881657 | I33: 0.672749 | J33: 1 | K33: 1 | L33: 0 | M33: 0 | N33: Si | O33: 0 | P33: 1 | Q33: 0 | R33: 1 | S33: 0 | T33: 0 | U33: 0 | V33: 0 | W33: nd | X33: 0 | Y33: 0 | Z33: 0 | AA33: 0 | AB33: 0 | AC33: 0 | AD33: 0 | AE33: 0 | AF33: 0 | AG33: 0 | AH33: Database | AI33: GBIF | AK33: https://www.inaturalist.org/observations/3968440
A34: P_violacea_126 | B34: 42617 | C34: Verano | D34: nd | E34: Badalona | F34: Barcelona | G34: Cataluña | H34: 41.440147 | I34: 2.2472849 | J34: 1 | K34: 1 | L34: 0 | M34: 0 | N34: Si | O34: 0 | P34: 1 | Q34: 0 | R34: 0 | S34: 0 | T34: 0 | U34: 0 | V34: 1 | W34: nd | X34: 1 | Y34: 0 | Z34: 0 | AA34: 1 | AB34: 0 | AC34: 0 | AD34: 0 | AE34: 0 | AF34: 0 | AG34: 0 | AH34: Redes Sociales | AI34: Instagram | AK34: https://www.instagram.com/p/BJ8FsLhgrEC/ | AL34: Tiene la región dorsal así como "hinchada"
A35: P_violacea_048 | B35: 42622 | C35: Verano | D35: nd | E35: Motril | F35: Granada | G35: Andalucía | H35: 36.717912 | I35: -3.5415474 | J35: 3 | K35: 0 | L35: 3 | M35: 0 | N35: nd | O35: 0 | P35: 1 | Q35: 2 | R35: 1 | S35: 0 | T35: 2 | U35: 0 | V35: 0 | W35: nd | X35: 1 | Y35: 0 | Z35: 0 | AA35: 0 | AB35: 1 | AC35: 0 | AD35: 0 | AE35: 0 | AF35: 0 | AG35: 0 | AH35: Redes Sociales | AI35: Twitter | AK35: https://twitter.com/losMotriles/status/774338161153568768 | AL35: Dando luz en playa a 2 crías!
A36: P_violacea_237 | B36: 42912 | C36: Verano | D36: nd | E36: El Garraf | F36: Barcelona | G36: Cataluña | H36: 41.198395 | I36: 1.9231849 | J36: 1 | K36: 1 | L36: 0 | M36: 0 | N36: No | O36: 0 | P36: 1 | Q36: 0 | R36: 1 | S36: 0 | T36: 0 | U36: 0 | V36: 0 | W36: nd | X36: 0 | Y36: 0 | Z36: 0 | AA36: 0 | AB36: 0 | AC36: 0 | AD36: 0 | AE36: 0 | AF36: 0 | AG36: 0 | AH36: Redes Sociales | AI36: Instagram | AK36: https://www.instagram.com/p/BVz9nP8FeiZ/ | AL36: Coords aproximadas
A37: P_violacea_037 | B37: 42917 | C37: Verano | D37: 0.37083333 | E37: Cala Montjoi | F37: Girona | G37: Cataluña | H37: 42.249115 | I37: 3.227598 | J37: 1 | K37: 1 | L37: 0 | M37: 0 | N37: Si | O37: 0 | P37: 0 | Q37: 1 | R37: 0 | S37: 0 | T37: 0 | U37: 0 | V37: 1 | W37: nd | X37: 1 | Y37: 0 | Z37: 0 | AA37: 1 | AB37: 0 | AC37: 0 | AD37: 0 | AE37: 0 | AF37: 0 | AG37: 0 | AH37: Database | AI37: GBIF | AK37: https://www.inaturalist.org/observations/90363596 | AL37: Tiene la región dorsal como "hinchada"
A38: P_violacea_049 | B38: 42949 | C38: Verano | D38: nd | E38: Valencia | F38: Valencia | G38: Comunidad Valenciana | J38: 1 | K38: 0 | L38: 0 | M38: 1 | N38: nd | O38: 0 | P38: 0 | Q38: 1 | R38: 0 | S38: 0 | T38: 0 | U38: 0 | V38: 1 | W38: nd | X38: 0 | Y38: 0 | Z38: 0 | AA38: 0 | AB38: 0 | AC38: 0 | AD38: 0 | AE38: 0 | AF38: 0 | AG38: 0 | AH38: Redes Sociales | AI38: Instagram | AK38: www.instagram.com/p/BXSTZaJg_4N | AL38: Coord imp, cuanta ya no existe. Pesca
A39: P_violacea_459 | B39: 42959 | C39: Verano | D39: 0.79166667 | E39: Isla de Cabrera, Es Fondalet | F39: Islas Baleares | G39: Islas Baleares | H39: 39.165367 | I39: 2.9474028 | J39: 1 | K39: 1 | L39: 0 | M39: 0 | N39: No | O39: 0 | P39: 1 | Q39: 0 | R39: 1 | S39: 0 | T39: 0 | U39: 0 | V39: 0 | W39: nd | X39: 1 | Y39: 0 | Z39: 0 | AA39: 1 | AB39: 0 | AC39: 0 | AD39: 0 | AE39: 0 | AF39: 0 | AG39: 0 | AH39: Database | AI39: iNaturalist | AK39: https://www.inaturalist.org/observations/317348920 | AL39: Parece tener región dorsal hinchado (quizás embarazada)
A40: P_violacea_050 | B40: 42963 | C40: Verano | D40: nd | E40: Caldas de Estrach | F40: Barcelona | G40: Cataluña | H40: 41.566685 | I40: 2.5254423 | J40: 1 | K40: 1 | L40: 0 | M40: 0 | N40: Si | O40: 0 | P40: 0 | Q40: 1 | R40: 0 | S40: 0 | T40: 0 | U40: 0 | V40: 1 | W40: nd | X40: 1 | Y40: 0 | Z40: 0 | AA40: 0 | AB40: 0 | AC40: 0 | AD40: 0 | AE40: 1 | AF40: 0 | AG40: 1 | AH40: Redes Sociales | AI40: Instagram | AK40: https://www.instagram.com/p/BX21NNjBey0/ | AL40: Cola pelada y parece mostrar estrés al "comprimir" el disco o es la sensación que da. Movimientos erráticos y varamientos en playa
...

Sheet Info_heridas
B2: Cosas a tener en cuenta para hacer en relación a las heridas

Sheet P_violacea_Heridas
A1: ID | B1: Fecha | C1: Estación | D1: Hora | E1: Ubicación | F1: Provincia | G1: Com_Autónoma | H1: Lat | I1: Long | J1: Inds | K1: Viva | L1: Muerta | M1: nd | N1: Heridas | O1: M_sex_SI | P1: H_sex_SI | Q1: nd_sex_SI | R1: M_sex_NO | S1: H_sex_NO | T1: nd_sex_NO | U1: Adult_SI | V1: Juv_SI | W1: New_SI | X1: Emb_SI | Y1: nd_SI | Z1: Adult_NO | AA1: Juv_NO | AB1: New_NO | AC1: Emb_NO | AD1: nd_NO | AE1: DW | AF1: N_heridas | AG1: Cabeza | AH1: Ala_izq | AI1: Ala_drch | AJ1: Dorso | AK1: Cola | AL1: Abdomen | AM1: Otros | AN1: Tipo | AO1: Severidad | AP1: Estado_ctrz | AQ1: Simetría | AR1: Obs_heridas | AS1: Fuente_tipo | AT1: Fuente | AU1: Link | AV1: Observaciones generales
A2: P_violacea_001 | B2: 45810 | C2: Verano | D2: nd | E2: Cala Vedella, Sant Josep (Ibiza) | F2: Islas Baleares | G2: Islas Baleares | H2: 38.913877 | I2: 1.2235663 | J2: 1 | K2: 1 | L2: 0 | M2: 0 | N2: No | O2: 0 | P2: 0 | Q2: 0 | R2: 0 | S2: 0 | T2: 1 | U2: 0 | V2: 0 | W2: 0 | X2: 0 | Y2: 0 | Z2: 0 | AA2: 0 | AB2: 0 | AC2: 0 | AD2: 1 | AE2: nd | AF2: NA | AS2: Redes Sociales | AT2: Instagram | AU2: https://www.instagram.com/reel/DKZbKj5tjsB/?igsh=d2xnbDBsM2FpaXRw | AV2: En orilla de la playa, aguas muy someras
A3: P_violacea_002 | B3: 45511 | C3: Verano | D3: 0.46319444 | E3: Marina Alta | F3: Alicante | G3: Comunidad Valenciana | H3: 38.664443 | I3: 0.16454548 | J3: 1 | K3: 1 | L3: 0 | M3: 0 | N3: Si | O3: 0 | P3: 1 | Q3: 0 | R3: 0 | S3: 0 | T3: 0 | U3: 1 | V3: 0 | W3: 0 | X3: 0 | Y3: 0 | Z3: 0 | AA3: 0 | AB3: 0 | AC3: 0 | AD3: 0 | AE3: nd | AF3: =SUM(AH3:AL3) -> 0 | AS3: Database | AT3: GBIF | AU3: https://www.inaturalist.org/observations/236888541 | AV3: Coordenadas ocultas y por ende aproximadas
A4: P_violacea_003 | B4: 45517 | C4: Verano | D4: 0.59791667 | E4: Rat-Penat | F4: Barcelona | G4: Cataluña | H4: 41.259323 | I4: 1.925179 | J4: 1 | K4: 1 | L4: 0 | M4: 0 | N4: Si | O4: 0 | P4: 1 | Q4: 0 | R4: 0 | S4: 0 | T4: 0 | U4: 1 | V4: 0 | W4: 0 | X4: 0 | Y4: 0 | Z4: 0 | AA4: 0 | AB4: 0 | AC4: 0 | AD4: 0 | AE4: nd | AF4: =SUM(AH4:AL4) -> 0 | AS4: Database | AT4: GBIF | AU4: https://www.inaturalist.org/observations/235534224 | AV4: Nadando por el puerto
A5: P_violacea_004 | B5: 45516 | C5: Verano | D5: 0.58680556 | E5: Pla de l'Avella | F5: Barcelona | G5: Cataluña | H5: 41.507573 | I5: 2.41472 | J5: 1 | K5: 1 | L5: 0 | M5: 0 | N5: Si | O5: 0 | P5: 1 | Q5: 0 | R5: 0 | S5: 0 | T5: 0 | U5: 0 | V5: 0 | W5: 0 | X5: 0 | Y5: 1 | Z5: 0 | AA5: 0 | AB5: 0 | AC5: 0 | AD5: 0 | AE5: nd | AF5: =SUM(AH5:AL5) -> 0 | AS5: Database | AT5: GBIF | AU5: https://www.inaturalist.org/observations/235315927 | AV5: Tiene la región dorsal como "hinchada"
A6: P_violacea_006 | B6: 45494 | C6: Verano | D6: 0.49652778 | E6: Garrucha | F6: Almería | G6: Andalucía | H6: 37.172542 | I6: -1.821586 | J6: 1 | K6: 1 | L6: 0 | M6: 0 | N6: Si | O6: 0 | P6: 1 | Q6: 0 | R6: 0 | S6: 0 | T6: 0 | U6: 1 | V6: 0 | W6: 0 | X6: 0 | Y6: 0 | Z6: 0 | AA6: 0 | AB6: 0 | AC6: 0 | AD6: 0 | AE6: nd | AF6: =SUM(AH6:AL6) -> 0 | AS6: Database | AT6: GBIF | AU6: https://www.inaturalist.org/observations/230749822 | AV6: It was swimming among the people unbothered and was beaching itself into the shore constantly. Any idea of what could be wrong with it??? It had a wound on the fin, seemed to be stressed or just unwell
A7: P_violacea_007 | B7: 45492 | C7: Verano | D7: 0.66041667 | E7: Playa La Roqueta, Guardamar del Segura | F7: Alicante | G7: Comunidad Valenciana | H7: 38.077839 | I7: -0.647482 | J7: 1 | K7: 1 | L7: 0 | M7: 0 | N7: No | O7: 0 | P7: 0 | Q7: 0 | R7: 0 | S7: 0 | T7: 1 | U7: 0 | V7: 0 | W7: 0 | X7: 0 | Y7: 0 | Z7: 0 | AA7: 0 | AB7: 0 | AC7: 0 | AD7: 1 | AE7: nd | AF7: NA | AS7: Database | AT7: GBIF | AU7: https://www.inaturalist.org/observations/230290665 | AV7: Muy cerca de la orilla
A8: P_violacea_011 | B8: 43672 | C8: Verano | D8: nd | E8: Cala del Bonete Grande | F8: Región de Murcia | G8: Región de Murcia | H8: 37.561861 | I8: -1.119447 | J8: 1 | K8: 1 | L8: 0 | M8: 0 | N8: Si | O8: 0 | P8: 1 | Q8: 0 | R8: 0 | S8: 0 | T8: 0 | U8: 1 | V8: 0 | W8: 0 | X8: 0 | Y8: 0 | Z8: 0 | AA8: 0 | AB8: 0 | AC8: 0 | AD8: 0 | AE8: nd | AF8: =SUM(AH8:AL8) -> 0 | AS8: Database | AT8: GBIF | AU8: https://observation.org/observation/297113619/
A9: P_violacea_012 | B9: 41508 | C9: Verano | D9: nd | E9: Cala Santanyí | F9: Islas Baleares | G9: Islas Baleares | H9: 39.322646 | I9: 3.1462631 | J9: 1 | K9: 0 | L9: 0 | M9: 1 | N9: No | O9: 0 | P9: 0 | Q9: 0 | R9: 0 | S9: 1 | T9: 0 | U9: 0 | V9: 0 | W9: 0 | X9: 0 | Y9: 0 | Z9: 1 | AA9: 0 | AB9: 0 | AC9: 0 | AD9: 0 | AE9: nd | AF9: NA | AS9: Database | AT9: GBIF | AU9: https://observation.org/observation/297108565/
A10: P_violacea_016 | B10: 44359 | C10: Verano | D10: 0.72083333 | E10: Portocolom | F10: Islas Baleares | G10: Islas Baleares | H10: 39.417119 | I10: 3.2616092 | J10: 1 | K10: 1 | L10: 0 | M10: 0 | N10: No | O10: 0 | P10: 0 | Q10: 0 | R10: 0 | S10: 0 | T10: 1 | U10: 0 | V10: 0 | W10: 0 | X10: 0 | Y10: 0 | Z10: 0 | AA10: 0 | AB10: 0 | AC10: 0 | AD10: 1 | AE10: nd | AF10: NA | AS10: Database | AT10: GBIF | AU10: https://www.inaturalist.org/observations/164288148 | AV10: Descansando sobre fondo arenoso
A11: P_violacea_017 | B11: 44037 | C11: Verano | D11: 0.56875 | E11: Ensenada de los Berengueles | F11: Granada | G11: Andalucía | H11: 36.72126 | I11: -3.72744 | J11: 1 | K11: 1 | L11: 0 | M11: 0 | N11: No | O11: 0 | P11: 0 | Q11: 0 | R11: 0 | S11: 1 | T11: 0 | U11: 0 | V11: 0 | W11: 0 | X11: 0 | Y11: 0 | Z11: 0 | AA11: 0 | AB11: 0 | AC11: 0 | AD11: 1 | AE11: nd | AF11: NA | AS11: Database | AT11: GBIF | AU11: https://www.inaturalist.org/observations/143898564 | AV11: Parece tener la región dorsal laterlamente "hinchada"
A12: P_violacea_018 | B12: 44762 | C12: Verano | D12: 0.42152778 | E12: Platja Grifeu | F12: Girona | G12: Cataluña | H12: 42.38658 | I12: 3.164809 | J12: 1 | K12: 1 | L12: 0 | M12: 0 | N12: Si | O12: 0 | P12: 0 | Q12: 1 | R12: 0 | S12: 0 | T12: 0 | U12: 0 | V12: 0 | W12: 0 | X12: 0 | Y12: 1 | Z12: 0 | AA12: 0 | AB12: 0 | AC12: 0 | AD12: 0 | AE12: nd | AF12: =SUM(AH12:AL12) -> 0 | AS12: Database | AT12: GBIF | AU12: https://www.inaturalist.org/observations/127125698
A13: P_violacea_019 | B13: 42385 | C13: Invierno | D13: 0.86041667 | F13: Islas Baleares | G13: Islas Baleares | H13: 38.632002 | I13: 0.78201 | J13: 1 | K13: 1 | L13: 0 | M13: 0 | N13: No | O13: 0 | P13: 0 | Q13: 0 | R13: 0 | S13: 0 | T13: 1 | U13: 0 | V13: 0 | W13: 0 | X13: 0 | Y13: 0 | Z13: 0 | AA13: 0 | AB13: 0 | AC13: 0 | AD13: 1 | AE13: nd | AF13: NA | AS13: Database | AT13: GBIF
A14: P_violacea_020 | B14: 44023 | C14: Verano | D14: nd | E14: Cala en Basset | F14: Islas Baleares | G14: Islas Baleares | H14: 39.597 | I14: 2.3526 | J14: 1 | K14: 1 | L14: 0 | M14: 0 | N14: Si | O14: 0 | P14: 0 | Q14: 1 | R14: 0 | S14: 0 | T14: 0 | U14: 0 | V14: 0 | W14: 0 | X14: 0 | Y14: 1 | Z14: 0 | AA14: 0 | AB14: 0 | AC14: 0 | AD14: 0 | AE14: nd | AF14: =SUM(AH14:AL14) -> 0 | AS14: Database | AT14: Obsdelmar | AU14: https://www.observadoresdelmar.es/Observations/214758 | AV14: Tiene la región dorsal como "hinchada" lateralmente
A15: P_violacea_022 | B15: 43333 | C15: Verano | D15: nd | E15: Arenales del Sol | F15: Alicante | G15: Comunidad Valenciana | H15: 38.2587 | I15: -0.5154 | J15: 1 | K15: 1 | L15: 0 | M15: 0 | N15: No | O15: 0 | P15: 0 | Q15: 0 | R15: 0 | S15: 0 | T15: 1 | U15: 0 | V15: 0 | W15: 0 | X15: 0 | Y15: 0 | Z15: 0 | AA15: 0 | AB15: 0 | AC15: 0 | AD15: 1 | AE15: nd | AF15: NA | AS15: Database | AT15: Obsdelmar | AU15: https://www.observadoresdelmar.es/Observations/213426
A16: P_violacea_023 | B16: 43317 | C16: Verano | D16: nd | E16: Bellavista | F16: Islas Baleares | G16: Islas Baleares | H16: 39.4804 | I16: 2.7277 | J16: 1 | K16: 1 | L16: 0 | M16: 0 | N16: Si | O16: 0 | P16: 1 | Q16: 0 | R16: 0 | S16: 0 | T16: 0 | U16: 0 | V16: 0 | W16: 0 | X16: 0 | Y16: 1 | Z16: 0 | AA16: 0 | AB16: 0 | AC16: 0 | AD16: 0 | AE16: nd | AF16: =SUM(AH16:AL16) -> 0 | AS16: Database | AT16: Obsdelmar | AU16: https://www.observadoresdelmar.es/Observations/210579
A17: P_violacea_025 | B17: 41509 | C17: Verano | D17: nd | E17: La Mata | F17: Alicante | G17: Comunidad Valenciana | H17: 38.0196 | I17: -0.6518 | J17: 1 | K17: 0 | L17: 1 | M17: 0 | N17: No | O17: 0 | P17: 0 | Q17: 0 | R17: 0 | S17: 0 | T17: 1 | U17: 0 | V17: 0 | W17: 0 | X17: 0 | Y17: 0 | Z17: 0 | AA17: 1 | AB17: 0 | AC17: 0 | AD17: 0 | AE17: nd | AF17: NA | AS17: Database | AT17: Obsdelmar | AU17: https://www.observadoresdelmar.es/Observations/213424 | AV17: Se ve muy pequeño y se puede estimar tamaño
A18: P_violacea_026 | B18: 43330 | C18: Verano | D18: nd | E18: San Francesc de s'Estany | F18: Islas Baleares | G18: Islas Baleares | H18: 38.833 | I18: 1.3903 | J18: 1 | K18: 1 | L18: 0 | M18: 0 | N18: Si | O18: 0 | P18: 1 | Q18: 0 | R18: 0 | S18: 0 | T18: 0 | U18: 1 | V18: 0 | W18: 0 | X18: 0 | Y18: 0 | Z18: 0 | AA18: 0 | AB18: 0 | AC18: 0 | AD18: 0 | AE18: nd | AF18: =SUM(AH18:AL18) -> 0 | AS18: Database | AT18: Obsdelmar | AU18: https://www.observadoresdelmar.es/Observations/210182 | AV18: Hola de nuevo! Os vuelvo a escribir ya que hoy estando en Ses Salines ( Ibiza) hemos estado con una raya que estaba como a un metro de profundidad donde había unos 10 metros, todo el rato estaba con nosotros cosa extraña pero pensábamos q las aletas le hacían gracia, tengo fotos y vídeos con ella pero el programa no me deja agregar más de una foto. Lo raro es que al rato hemos divisas otra raya diferente desde el barco en la misma zona aunque esta parecía enferma y estaba todo el rato en superficie y tenía señales de herida, no se si están ahí por un casual o realmente están enfermas por alguna razón. No se que puedo hacer al respecto por eso os escribo y espero que me respondan porque me he ido del lugar preocupada ya que seguía una de ella por superficie. Muchas gracias.,Hola Monica,<br /> Esta raya es una raya látigo violeta, es habitual verlas mar adentro pero en su período reproductivo tienden a acercarse a la costa. Si te fijas bien la raya de la foto tiene una mancha blanca, seguramente provocada por el macho en el momento del apareamiento, lo que también explicaría el extraño comportamiento que describes, <br /> <br /> saludos y muchas gracias por tu observación!<br /> <br /> Claudio
A19: P_violacea_027 | B19: 43328 | C19: Verano | D19: nd | E19: Torredembarra | F19: Tarragona | G19: Cataluña | H19: 41.1436 | I19: 1.4147 | J19: 1 | K19: 1 | L19: 0 | M19: 0 | N19: No | O19: 0 | P19: 0 | Q19: 0 | R19: 1 | S19: 0 | T19: 0 | U19: 0 | V19: 0 | W19: 0 | X19: 0 | Y19: 0 | Z19: 1 | AA19: 0 | AB19: 0 | AC19: 0 | AD19: 0 | AE19: nd | AF19: NA | AS19: Database | AT19: Obsdelmar | AU19: https://www.observadoresdelmar.es/Observations/210173 | AV19: Nedant per fons sorrenc i entre dues barres de roques.,Muchas gracias Pere,<br /> <br /> Podrías enviarme la foto a mi correo por favor, creo que es un macho pero no lo puedo ver desde aquí,<br /> <br /> muchas gracias!<br /> <br /> Claudio
A20: P_violacea_028 | B20: 42595 | C20: Verano | D20: nd | E20: Sa Tuna | F20: Girona | G20: Cataluña | H20: 41.9601 | I20: 3.2315 | J20: 1 | K20: 1 | L20: 0 | M20: 0 | N20: Si | O20: 0 | P20: 1 | Q20: 0 | R20: 0 | S20: 0 | T20: 0 | U20: 1 | V20: 0 | W20: 0 | X20: 0 | Y20: 0 | Z20: 0 | AA20: 0 | AB20: 0 | AC20: 0 | AD20: 0 | AE20: nd | AF20: =SUM(AH20:AL20) -> 0 | AS20: Database | AT20: Obsdelmar | AU20: https://www.observadoresdelmar.es/Observations/206216 | AV20: Tengo alguna foto más. No estoy al 100% seguro de que sea esta especie,Muchas gracias Juan! He validado la especie en base a las otras fotos que me mandaste. Tu observación ha sido fundamental para poder confirmar la presencia de esta especie en la Costa Brava: este es el principal valor de "Observadores del mar"! Confirmaría que esta especie se ha dejado ver mucho más al norte y mucho más frecuentemente que nunca en aguas litorales del Mediterráneo noroccidental.
A21: P_violacea_029 | B21: 43328 | C21: Verano | D21: nd | E21: La Azohía | F21: Región de Murcia | G21: Región de Murcia | H21: 37.5526 | I21: -1.1784 | J21: 2 | K21: 2 | L21: 0 | M21: 0 | N21: No | O21: 0 | P21: 0 | Q21: 0 | R21: 1 | S21: 1 | T21: 0 | U21: 0 | V21: 0 | W21: 0 | X21: 0 | Y21: 0 | Z21: 2 | AA21: 0 | AB21: 0 | AC21: 0 | AD21: 0 | AE21: nd | AF21: NA | AS21: Database | AT21: Obsdelmar | AU21: https://www.observadoresdelmar.es/Observations/213425 | AV21: Apareamiento
A22: P_violacea_030 | B22: 41136 | C22: Verano | D22: nd | E22: Torrevieja | F22: Alicante | G22: Comunidad Valenciana | H22: 38.006 | I22: -0.6494 | J22: 1 | K22: 1 | L22: 0 | M22: 0 | N22: Si | O22: 0 | P22: 0 | Q22: 1 | R22: 0 | S22: 0 | T22: 0 | U22: 0 | V22: 0 | W22: 1 | X22: 0 | Y22: 0 | Z22: 0 | AA22: 0 | AB22: 0 | AC22: 0 | AD22: 0 | AE22: nd | AF22: =SUM(AH22:AL22) -> 0 | AS22: Database | AT22: Obsdelmar | AU22: https://www.observadoresdelmar.es/Observations/213423 | AV22: Es MUY pequeño y gran herida
A23: P_violacea_031 | B23: 42159 | C23: Verano | D23: nd | E23: Torrevieja | F23: Alicante | G23: Comunidad Valenciana | H23: 37.9854 | I23: -0.6054 | J23: 1 | K23: 0 | L23: 1 | M23: 0 | N23: Si | O23: 0 | P23: 0 | Q23: 1 | R23: 0 | S23: 0 | T23: 0 | U23: 1 | V23: 0 | W23: 0 | X23: 0 | Y23: 0 | Z23: 0 | AA23: 0 | AB23: 0 | AC23: 0 | AD23: 0 | AE23: nd | AF23: =SUM(AH23:AL23) -> 0 | AS23: Database | AT23: Obsdelmar | AU23: https://marineinfo.org/id/dataset/6526 | AV23: Tamaño estimado 70-80 cm<br /> Peso estimado 20 kg,Hola J. Antonio, muchas gracias por tu observación. Esta es una especie muy interesante, de la cual no hay muchos reportes en estas costas, si puedes enviarme más fotos estaría muy bien, saludos
A24: P_violacea_032 | B24: 43303 | C24: Verano | D24: nd | E24: Cap de Formentor | F24: Islas Baleares | G24: Islas Baleares | H24: 39.9629 | I24: 3.2107 | J24: 1 | K24: 1 | L24: 0 | M24: 0 | N24: Si | O24: 0 | P24: 1 | Q24: 0 | R24: 0 | S24: 0 | T24: 0 | U24: 0 | V24: 0 | W24: 0 | X24: 0 | Y24: 1 | Z24: 0 | AA24: 0 | AB24: 0 | AC24: 0 | AD24: 0 | AE24: nd | AF24: =SUM(AH24:AL24) -> 0 | AS24: Database | AT24: Obsdelmar | AU24: https://www.observadoresdelmar.es/Observations/210402 | AV24: Foto de Gregor Schlüter,Muchas gracias por esta observación Tramuntana Diving! Esta especie es muy importante en nuestro #retoraya ya que podría ser indicadora del cambio climático,<br /> <br /> saludos<br /> <br /> Claudio
A25: P_violacea_033 | B25: 43997 | C25: Verano | D25: nd | E25: Águilas | F25: Región de Murcia | G25: Región de Murcia | H25: 37.4115 | I25: -1.5587 | J25: 1 | K25: 1 | L25: 0 | M25: 0 | N25: Si | O25: 0 | P25: 1 | Q25: 0 | R25: 0 | S25: 0 | T25: 0 | U25: 1 | V25: 0 | W25: 0 | X25: 0 | Y25: 0 | Z25: 0 | AA25: 0 | AB25: 0 | AC25: 0 | AD25: 0 | AE25: nd | AF25: =SUM(AH25:AL25) -> 0 | AS25: Database | AT25: Facebook | AU25: https://www.facebook.com/cronicas.naturales.torrevieja/videos/575727133369145/?t=21 | AV25: Observado y grabado por bañistas en la orilla https://www.facebook.com/cronicas.naturales.torrevieja/videos/575727133369145/?t=21,
A26: P_violacea_035 | B26: 43306 | C26: Verano | D26: nd | F26: Barcelona | G26: Cataluña | H26: 41.235883 | I26: 1.8290563 | J26: 1 | K26: 1 | L26: 0 | M26: 0 | N26: Si | O26: 0 | P26: 0 | Q26: 1 | R26: 0 | S26: 0 | T26: 0 | U26: 0 | V26: 0 | W26: 0 | X26: 0 | Y26: 1 | Z26: 0 | AA26: 0 | AB26: 0 | AC26: 0 | AD26: 0 | AE26: nd | AF26: =SUM(AH26:AL26) -> 0 | AS26: Database | AT26: Obsdelmar | AU26: https://www.observadoresdelmar.es/Observations/210025 | AV26: Tiene coords raras (40.9790000, 1.9335000)... lo he aproximado a BCN/Garraf que es el punto de costa más cercano porque a 1 metro en alta mar es imposible! Comentario obsdelmar: Lo he puesto en conocimiento del 112 por si la raya sufria algun daño de las personas o las personas de la raya ,ya que estaba en la misma orilla con solo medio metro de profundidad,mide algo mas de un metro con cola incluida,Hola Genoveva,<br /> <br /> Muchas gracias por observación, es muy interesante!. A pesar de que se han avistado muchas rayas de esta especie este verano, es la primera observación de una raya en estas condiciones, una pena. <br /> <br /> saludos<br /> <br /> Claudio
A27: P_violacea_036 | B27: 44035 | C27: Verano | D27: 0.47638889 | E27: La Almadraba de Monteleva | F27: Almería | G27: Andalucía | H27: 36.723761 | I27: -2.194025 | J27: 1 | K27: 1 | L27: 0 | M27: 0 | N27: Si | O27: 0 | P27: 1 | Q27: 0 | R27: 0 | S27: 0 | T27: 0 | U27: 1 | V27: 0 | W27: 0 | X27: 0 | Y27: 0 | Z27: 0 | AA27: 0 | AB27: 0 | AC27: 0 | AD27: 0 | AE27: nd | AF27: =SUM(AH27:AL27) -> 0 | AS27: Database | AT27: GBIF | AU27: https://www.inaturalist.org/observations/92599368
A28: P_violacea_037 | B28: 42917 | C28: Verano | D28: 0.37083333 | E28: Cala Montjoi | F28: Girona | G28: Cataluña | H28: 42.249115 | I28: 3.227598 | J28: 1 | K28: 1 | L28: 0 | M28: 0 | N28: Si | O28: 0 | P28: 0 | Q28: 1 | R28: 0 | S28: 0 | T28: 0 | U28: 0 | V28: 0 | W28: 0 | X28: 0 | Y28: 1 | Z28: 0 | AA28: 0 | AB28: 0 | AC28: 0 | AD28: 0 | AE28: nd | AF28: =SUM(AH28:AL28) -> 0 | AS28: Database | AT28: GBIF | AU28: https://www.inaturalist.org/observations/90363596 | AV28: Tiene la región dorsal como "hinchada"
A29: P_violacea_038 | B29: 43317 | C29: Verano | D29: 0.90347222 | E29: Sóller | F29: Islas Baleares | G29: Islas Baleares | H29: 39.800228 | I29: 2.6855915 | J29: 1 | K29: 1 | L29: 0 | M29: 0 | N29: Si | O29: 0 | P29: 0 | Q29: 1 | R29: 0 | S29: 0 | T29: 0 | U29: 1 | V29: 0 | W29: 0 | X29: 0 | Y29: 0 | Z29: 0 | AA29: 0 | AB29: 0 | AC29: 0 | AD29: 0 | AE29: nd | AF29: =SUM(AH29:AL29) -> 0 | AS29: Database | AT29: GBIF | AU29: https://www.inaturalist.org/observations/15205269
A30: P_violacea_039 | B30: 44022 | C30: Verano | D30: 0.5625 | E30: Cala la Tía Antonia | F30: Almería | G30: Andalucía | H30: 37.357948 | I30: -1.662135 | J30: 1 | K30: 1 | L30: 0 | M30: 0 | N30: Si | O30: 0 | P30: 1 | Q30: 0 | R30: 0 | S30: 0 | T30: 0 | U30: 1 | V30: 0 | W30: 0 | X30: 0 | Y30: 0 | Z30: 0 | AA30: 0 | AB30: 0 | AC30: 0 | AD30: 0 | AE30: nd | AF30: =SUM(AH30:AL30) -> 0 | AS30: Database | AT30: GBIF | AU30: https://www.inaturalist.org/observations/52570881
A31: P_violacea_040 | B31: 42596 | C31: Verano | D31: 0.90277778 | E31: Islas Columbretes | F31: Castellón | G31: Comunidad Valenciana | H31: 39.881657 | I31: 0.672749 | J31: 1 | K31: 1 | L31: 0 | M31: 0 | N31: Si | O31: 0 | P31: 1 | Q31: 0 | R31: 0 | S31: 0 | T31: 0 | U31: 1 | V31: 0 | W31: 0 | X31: 0 | Y31: 0 | Z31: 0 | AA31: 0 | AB31: 0 | AC31: 0 | AD31: 0 | AE31: nd | AF31: =SUM(AH31:AL31) -> 0 | AS31: Database | AT31: GBIF | AU31: https://www.inaturalist.org/observations/3968440
A32: P_violacea_042 | B32: 41506 | C32: Verano | D32: nd | E32: Islas Columbretes | F32: Castellón | G32: Comunidad Valenciana | H32: 39.890047 | I32: 0.66895061 | J32: 1 | K32: 1 | L32: 0 | M32: 0 | N32: Si | O32: 0 | P32: 1 | Q32: 0 | R32: 0 | S32: 0 | T32: 0 | U32: 1 | V32: 0 | W32: 0 | X32: 0 | Y32: 0 | Z32: 0 | AA32: 0 | AB32: 0 | AC32: 0 | AD32: 0 | AE32: nd | AF32: =SUM(AH32:AL32) -> 0 | AS32: Redes Sociales | AT32: YouTube | AU32: https://www.youtube.com/watch?v=FTKvVXQBYJ8 | AV32: Parece que está embarazada!
A33: P_violacea_043 | B33: 42573 | C33: Verano | D33: nd | E33: Enix | F33: Almería | G33: Andalucía | H33: 36.817942 | I33: -2.5332835 | J33: 2 | K33: 2 | L33: 0 | M33: 0 | N33: No | O33: 0 | P33: 0 | Q33: 0 | R33: 1 | S33: 1 | T33: 0 | U33: 0 | V33: 0 | W33: 0 | X33: 0 | Y33: 0 | Z33: 2 | AA33: 0 | AB33: 0 | AC33: 0 | AD33: 0 | AE33: nd | AF33: NA | AS33: Redes Sociales | AT33: Vimeo | AU33: https://vimeo.com/175886064 | AV33: Apareamiento
A34: P_violacea_044 | B34: 42581 | C34: Verano | D34: nd | E34: Moraira | F34: Alicante | G34: Comunidad Valenciana | H34: 38.685822 | I34: 0.15444061 | J34: 1 | K34: 1 | L34: 0 | M34: 0 | N34: Si | O34: 0 | P34: 1 | Q34: 0 | R34: 0 | S34: 0 | T34: 0 | U34: 1 | V34: 0 | W34: 0 | X34: 0 | Y34: 0 | Z34: 0 | AA34: 0 | AB34: 0 | AC34: 0 | AD34: 0 | AE34: nd | AF34: =SUM(AH34:AL34) -> 0 | AS34: Redes Sociales | AT34: Facebook | AU34: www.facebook.com/L.Elasmogrup/posts/542435975957971 | AV34: Embarazada
A35: P_violacea_045 | B35: 42581 | C35: Verano | D35: nd | E35: Santa Margalida | F35: Islas Baleares | G35: Islas Baleares | H35: 39.776234 | I35: 3.1497189 | J35: 1 | K35: 1 | L35: 0 | M35: 0 | N35: No | O35: 0 | P35: 0 | Q35: 0 | R35: 0 | S35: 0 | T35: 1 | U35: 0 | V35: 0 | W35: 0 | X35: 0 | Y35: 0 | Z35: 1 | AA35: 0 | AB35: 0 | AC35: 0 | AD35: 0 | AE35: nd | AF35: NA | AS35: Redes Sociales | AT35: Twitter | AU35: https://twitter.com/irenina14/status/759349778249572352 | AV35: En playa y fue reorientada
A36: P_violacea_047 | B36: 42590 | C36: Verano | D36: nd | E36: Barcelona | F36: Barcelona | G36: Cataluña | H36: 41.378808 | I36: 2.1949402 | J36: 1 | K36: 1 | L36: 0 | M36: 0 | N36: No | O36: 0 | P36: 0 | Q36: 0 | R36: 0 | S36: 1 | T36: 0 | U36: 0 | V36: 0 | W36: 0 | X36: 0 | Y36: 0 | Z36: 1 | AA36: 0 | AB36: 0 | AC36: 0 | AD36: 0 | AE36: nd | AF36: NA | AS36: Redes Sociales | AT36: Twitter | AU36: https://twitter.com/rtvenoticies/status/762408730164072448
A37: P_violacea_050 | B37: 42963 | C37: Verano | D37: nd | E37: Caldas de Estrach | F37: Barcelona | G37: Cataluña | H37: 41.566685 | I37: 2.5254423 | J37: 1 | K37: 1 | L37: 0 | M37: 0 | N37: Si | O37: 0 | P37: 0 | Q37: 1 | R37: 0 | S37: 0 | T37: 0 | U37: 0 | V37: 0 | W37: 0 | X37: 0 | Y37: 1 | Z37: 0 | AA37: 0 | AB37: 0 | AC37: 0 | AD37: 0 | AE37: nd | AF37: =SUM(AH37:AL37) -> 0 | AS37: Redes Sociales | AT37: Instagram | AU37: https://www.instagram.com/p/BX21NNjBey0/ | AV37: Cola pelada y parece mostrar estrés al "comprimir" el disco o es la sensación que da. Movimientos erráticos y varamientos en playa
A38: P_violacea_052 | B38: 43225 | C38: Primavera | D38: nd | E38: Playa Arrabassada | F38: Tarragona | G38: Cataluña | H38: 41.118889 | I38: 1.2781905 | J38: 1 | K38: 1 | L38: 0 | M38: 0 | N38: No | O38: 0 | P38: 0 | Q38: 0 | R38: 0 | S38: 0 | T38: 1 | U38: 0 | V38: 0 | W38: 0 | X38: 0 | Y38: 0 | Z38: 0 | AA38: 0 | AB38: 0 | AC38: 0 | AD38: 1 | AE38: nd | AF38: NA | AS38: Redes Sociales | AT38: Instagram | AU38: www.instagram.com/p/BmAtL64jV7m
A39: P_violacea_053 | B39: 43300 | C39: Verano | D39: nd | E39: Llançà | F39: Girona | G39: Cataluña | H39: 42.361303 | I39: 3.1661867 | J39: 1 | K39: 1 | L39: 0 | M39: 0 | N39: Si | O39: 0 | P39: 1 | Q39: 0 | R39: 0 | S39: 0 | T39: 0 | U39: 1 | V39: 0 | W39: 0 | X39: 0 | Y39: 0 | Z39: 0 | AA39: 0 | AB39: 0 | AC39: 0 | AD39: 0 | AE39: nd | AF39: =SUM(AH39:AL39) -> 0 | AS39: Redes Sociales | AT39: Instagram | AU39: www.instagram.com/p/Blamn6VnUT_
A40: P_violacea_057 | B40: 43309 | C40: Verano | D40: nd | E40: Cólera | F40: Girona | G40: Cataluña | H40: 42.405056 | I40: 3.1573966 | J40: 1 | K40: 1 | L40: 0 | M40: 0 | N40: Si | O40: 0 | P40: 0 | Q40: 1 | R40: 0 | S40: 0 | T40: 0 | U40: 1 | V40: 0 | W40: 0 | X40: 0 | Y40: 0 | Z40: 0 | AA40: 0 | AB40: 0 | AC40: 0 | AD40: 0 | AE40: nd | AF40: =SUM(AH40:AL40) -> 0 | AS40: Redes Sociales | AT40: Instagram | AU40: www.instagram.com/p/BlyYoZhAZdc
...

Sheet Conteo_year
A1: Año | B1: Ene | C1: Feb | D1: Mar | E1: Abr | F1: May | G1: Jun | H1: Jul | I1: Ago | J1: Sep | K1: Oct | L1: Nov | M1: Dic | N1: Total year
A2: 1987 | B2: =SUMIFS(P_violacea_Spain_Med!$J:$J, P_violacea_Spain_Med!$B:$B, ">="&DATE(1987,1,1), P_violacea_Spain_Med!$B:$B, "<="&DATE(1987,1,31)) -> 0 | C2: =SUMIFS(P_violacea_Spain_Med!$J:$J, P_violacea_Spain_Med!$B:$B, ">="&DATE(1987,2,1), P_violacea_Spain_Med!$B:$B, "<="&DATE(1987,2,28)) -> 0 | D2: =SUMIFS(P_violacea_Spain_Med!$J:$J, P_violacea_Spain_Med!$B:$B, ">="&DATE(1987,3,1), P_violacea_Spain_Med!$B:$B, "<="&DATE(1987,3,31)) -> 0 | E2: =SUMIFS(P_violacea_Spain_Med!$J:$J, P_violacea_Spain_Med!$B:$B, ">="&DATE(1987,4,1), P_violacea_Spain_Med!$B:$B, "<="&DATE(1987,4,30)) -> 0 | F2: =SUMIFS(P_violacea_Spain_Med!$J:$J, P_violacea_Spain_Med!$B:$B, ">="&DATE(1987,5,1), P_violacea_Spain_Med!$B:$B, "<="&DATE(1987,5,31)) -> 0 | G2: =SUMIFS(P_violacea_Spain_Med!$J:$J, P_violacea_Spain_Med!$B:$B, ">="&DATE(1987,6,1), P_violacea_Spain_Med!$B:$B, "<="&DATE(1987,6,30)) -> 0 | H2: =SUMIFS(P_violacea_Spain_Med!$J:$J, P_violacea_Spain_Med!$B:$B, ">="&DATE(1987,7,1), P_violacea_Spain_Med!$B:$B, "<="&DATE(1987,7,31)) -> 1 | I2: =SUMIFS(P_violacea_Spain_Med!$J:$J, P_violacea_Spain_Med!$B:$B, ">="&DATE(1987,8,1), P_violacea_Spain_Med!$B:$B, "<="&DATE(1987,8,31)) -> 0 | J2: =SUMIFS(P_violacea_Spain_Med!$J:$J, P_violacea_Spain_Med!$B:$B, ">="&DATE(1987,9,1), P_violacea_Spain_Med!$B:$B, "<="&DATE(1987,9,30)) -> 0 | K2: =SUMIFS(P_violacea_Spain_Med!$J:$J, P_violacea_Spain_Med!$B:$B, ">="&DATE(1987,10,1), P_violacea_Spain_Med!$B:$B, "<="&DATE(1987,10,31)) -> 0 | L2: =SUMIFS(P_violacea_Spain_Med!$J:$J, P_violacea_Spain_Med!$B:$B, ">="&DATE(1987,11,1), P_violacea_Spain_Med!$B:$B, "<="&DATE(1987,11,30)) -> 0 | M2: =SUMIFS(P_violacea_Spain_Med!$J:$J, P_violacea_Spain_Med!$B:$B, ">="&DATE(1987,12,1), P_violacea_Spain_Med!$B:$B, "<="&DATE(1987,12,31)) -> 0 | N2: =SUM($B2:$M2) -> 1
A3: 2005 | B3: =SUMIFS(P_violacea_Spain_Med!$J:$J, P_violacea_Spain_Med!$B:$B, ">="&DATE(2005,1,1), P_violacea_Spain_Med!$B:$B, "<="&DATE(2005,1,31)) -> 0 | C3: =SUMIFS(P_violacea_Spain_Med!$J:$J, P_violacea_Spain_Med!$B:$B, ">="&DATE(2005,2,1), P_violacea_Spain_Med!$B:$B, "<="&DATE(2005,2,28)) -> 0 | D3: =SUMIFS(P_violacea_Spain_Med!$J:$J, P_violacea_Spain_Med!$B:$B, ">="&DATE(2005,3,1), P_violacea_Spain_Med!$B:$B, "<="&DATE(2005,3,31)) -> 0 | E3: =SUMIFS(P_violacea_Spain_Med!$J:$J, P_violacea_Spain_Med!$B:$B, ">="&DATE(2005,4,1), P_violacea_Spain_Med!$B:$B, "<="&DATE(2005,4,30)) -> 0 | F3: =SUMIFS(P_violacea_Spain_Med!$J:$J, P_violacea_Spain_Med!$B:$B, ">="&DATE(2005,5,1), P_violacea_Spain_Med!$B:$B, "<="&DATE(2005,5,31)) -> 0 | G3: =SUMIFS(P_violacea_Spain_Med!$J:$J, P_violacea_Spain_Med!$B:$B, ">="&DATE(2005,6,1), P_violacea_Spain_Med!$B:$B, "<="&DATE(2005,6,30)) -> 0 | H3: =SUMIFS(P_violacea_Spain_Med!$J:$J, P_violacea_Spain_Med!$B:$B, ">="&DATE(2005,7,1), P_violacea_Spain_Med!$B:$B, "<="&DATE(2005,7,31)) -> 0 | I3: =SUMIFS(P_violacea_Spain_Med!$J:$J, P_violacea_Spain_Med!$B:$B, ">="&DATE(2005,8,1), P_violacea_Spain_Med!$B:$B, "<="&DATE(2005,8,31)) -> 1 | J3: =SUMIFS(P_violacea_Spain_Med!$J:$J, P_violacea_Spain_Med!$B:$B, ">="&DATE(2005,9,1), P_violacea_Spain_Med!$B:$B, "<="&DATE(2005,9,30)) -> 0 | K3: =SUMIFS(P_violacea_Spain_Med!$J:$J, P_violacea_Spain_Med!$B:$B, ">="&DATE(2005,10,1), P_violacea_Spain_Med!$B:$B, "<="&DATE(2005,10,31)) -> 0 | L3: =SUMIFS(P_violacea_Spain_Med!$J:$J, P_violacea_Spain_Med!$B:$B, ">="&DATE(2005,11,1), P_violacea_Spain_Med!$B:$B, "<="&DATE(2005,11,30)) -> 0 | M3: =SUMIFS(P_violacea_Spain_Med!$J:$J, P_violacea_Spain_Med!$B:$B, ">="&DATE(2005,12,1), P_violacea_Spain_Med!$B:$B, "<="&DATE(2005,12,31)) -> 0 | N3: =SUM($B3:$M3) -> 1
A4: 2006 | B4: =SUMIFS(P_violacea_Spain_Med!$J:$J, P_violacea_Spain_Med!$B:$B, ">="&DATE(2006,1,1), P_violacea_Spain_Med!$B:$B, "<="&DATE(2006,1,31)) -> 0 | C4: =SUMIFS(P_violacea_Spain_Med!$J:$J, P_violacea_Spain_Med!$B:$B, ">="&DATE(2006,2,1), P_violacea_Spain_Med!$B:$B, "<="&DATE(2006,2,28)) -> 0 | D4: =SUMIFS(P_violacea_Spain_Med!$J:$J, P_violacea_Spain_Med!$B:$B, ">="&DATE(2006,3,1), P_violacea_Spain_Med!$B:$B, "<="&DATE(2006,3,31)) -> 0 | E4: =SUMIFS(P_violacea_Spain_Med!$J:$J, P_violacea_Spain_Med!$B:$B, ">="&DATE(2006,4,1), P_violacea_Spain_Med!$B:$B, "<="&DATE(2006,4,30)) -> 0 | F4: =SUMIFS(P_violacea_Spain_Med!$J:$J, P_violacea_Spain_Med!$B:$B, ">="&DATE(2006,5,1), P_violacea_Spain_Med!$B:$B, "<="&DATE(2006,5,31)) -> 0 | G4: =SUMIFS(P_violacea_Spain_Med!$J:$J, P_violacea_Spain_Med!$B:$B, ">="&DATE(2006,6,1), P_violacea_Spain_Med!$B:$B, "<="&DATE(2006,6,30)) -> 0 | H4: =SUMIFS(P_violacea_Spain_Med!$J:$J, P_violacea_Spain_Med!$B:$B, ">="&DATE(2006,7,1), P_violacea_Spain_Med!$B:$B, "<="&DATE(2006,7,31)) -> 1 | I4: =SUMIFS(P_violacea_Spain_Med!$J:$J, P_violacea_Spain_Med!$B:$B, ">="&DATE(2006,8,1), P_violacea_Spain_Med!$B:$B, "<="&DATE(2006,8,31)) -> 0 | J4: =SUMIFS(P_violacea_Spain_Med!$J:$J, P_violacea_Spain_Med!$B:$B, ">="&DATE(2006,9,1), P_violacea_Spain_Med!$B:$B, "<="&DATE(2006,9,30)) -> 0 | K4: =SUMIFS(P_violacea_Spain_Med!$J:$J, P_violacea_Spain_Med!$B:$B, ">="&DATE(2006,10,1), P_violacea_Spain_Med!$B:$B, "<="&DATE(2006,10,31)) -> 0 | L4: =SUMIFS(P_violacea_Spain_Med!$J:$J, P_violacea_Spain_Med!$B:$B, ">="&DATE(2006,11,1), P_violacea_Spain_Med!$B:$B, "<="&DATE(2006,11,30)) -> 0 | M4: =SUMIFS(P_violacea_Spain_Med!$J:$J, P_violacea_Spain_Med!$B:$B, ">="&DATE(2006,12,1), P_violacea_Spain_Med!$B:$B, "<="&DATE(2006,12,31)) -> 0 | N4: =SUM($B4:$M4) -> 1
A5: 2007 | B5: =SUMIFS(P_violacea_Spain_Med!$J:$J, P_violacea_Spain_Med!$B:$B, ">="&DATE(2007,1,1), P_violacea_Spain_Med!$B:$B, "<="&DATE(2007,1,31)) -> 0 | C5: =SUMIFS(P_violacea_Spain_Med!$J:$J, P_violacea_Spain_Med!$B:$B, ">="&DATE(2007,2,1), P_violacea_Spain_Med!$B:$B, "<="&DATE(2007,2,28)) -> 0 | D5: =SUMIFS(P_violacea_Spain_Med!$J:$J, P_violacea_Spain_Med!$B:$B, ">="&DATE(2007,3,1), P_violacea_Spain_Med!$B:$B, "<="&DATE(2007,3,31)) -> 0 | E5: =SUMIFS(P_violacea_Spain_Med!$J:$J, P_violacea_Spain_Med!$B:$B, ">="&DATE(2007,4,1), P_violacea_Spain_Med!$B:$B, "<="&DATE(2007,4,30)) -> 0 | F5: =SUMIFS(P_violacea_Spain_Med!$J:$J, P_violacea_Spain_Med!$B:$B, ">="&DATE(2007,5,1), P_violacea_Spain_Med!$B:$B, "<="&DATE(2007,5,31)) -> 0 | G5: =SUMIFS(P_violacea_Spain_Med!$J:$J, P_violacea_Spain_Med!$B:$B, ">="&DATE(2007,6,1), P_violacea_Spain_Med!$B:$B, "<="&DATE(2007,6,30)) -> 0 | H5: =SUMIFS(P_violacea_Spain_Med!$J:$J, P_violacea_Spain_Med!$B:$B, ">="&DATE(2007,7,1), P_violacea_Spain_Med!$B:$B, "<="&DATE(2007,7,31)) -> 0 | I5: =SUMIFS(P_violacea_Spain_Med!$J:$J, P_violacea_Spain_Med!$B:$B, ">="&DATE(2007,8,1), P_violacea_Spain_Med!$B:$B, "<="&DATE(2007,8,31)) -> 1 | J5: =SUMIFS(P_violacea_Spain_Med!$J:$J, P_violacea_Spain_Med!$B:$B, ">="&DATE(2007,9,1), P_violacea_Spain_Med!$B:$B, "<="&DATE(2007,9,30)) -> 3 | K5: =SUMIFS(P_violacea_Spain_Med!$J:$J, P_violacea_Spain_Med!$B:$B, ">="&DATE(2007,10,1), P_violacea_Spain_Med!$B:$B, "<="&DATE(2007,10,31)) -> 0 | L5: =SUMIFS(P_violacea_Spain_Med!$J:$J, P_violacea_Spain_Med!$B:$B, ">="&DATE(2007,11,1), P_violacea_Spain_Med!$B:$B, "<="&DATE(2007,11,30)) -> 0 | M5: =SUMIFS(P_violacea_Spain_Med!$J:$J, P_violacea_Spain_Med!$B:$B, ">="&DATE(2007,12,1), P_violacea_Spain_Med!$B:$B, "<="&DATE(2007,12,31)) -> 0 | N5: =SUM($B5:$M5) -> 4
A6: 2008 | B6: =SUMIFS(P_violacea_Spain_Med!$J:$J, P_violacea_Spain_Med!$B:$B, ">="&DATE(2008,1,1), P_violacea_Spain_Med!$B:$B, "<="&DATE(2008,1,31)) -> 0 | C6: =SUMIFS(P_violacea_Spain_Med!$J:$J, P_violacea_Spain_Med!$B:$B, ">="&DATE(2008,2,1), P_violacea_Spain_Med!$B:$B, "<="&DATE(2008,2,28)) -> 0 | D6: =SUMIFS(P_violacea_Spain_Med!$J:$J, P_violacea_Spain_Med!$B:$B, ">="&DATE(2008,3,1), P_violacea_Spain_Med!$B:$B, "<="&DATE(2008,3,31)) -> 0 | E6: =SUMIFS(P_violacea_Spain_Med!$J:$J, P_violacea_Spain_Med!$B:$B, ">="&DATE(2008,4,1), P_violacea_Spain_Med!$B:$B, "<="&DATE(2008,4,30)) -> 0 | F6: =SUMIFS(P_violacea_Spain_Med!$J:$J, P_violacea_Spain_Med!$B:$B, ">="&DATE(2008,5,1), P_violacea_Spain_Med!$B:$B, "<="&DATE(2008,5,31)) -> 0 | G6: =SUMIFS(P_violacea_Spain_Med!$J:$J, P_violacea_Spain_Med!$B:$B, ">="&DATE(2008,6,1), P_violacea_Spain_Med!$B:$B, "<="&DATE(2008,6,30)) -> 0 | H6: =SUMIFS(P_violacea_Spain_Med!$J:$J, P_violacea_Spain_Med!$B:$B, ">="&DATE(2008,7,1), P_violacea_Spain_Med!$B:$B, "<="&DATE(2008,7,31)) -> 0 | I6: =SUMIFS(P_violacea_Spain_Med!$J:$J, P_violacea_Spain_Med!$B:$B, ">="&DATE(2008,8,1), P_violacea_Spain_Med!$B:$B, "<="&DATE(2008,8,31)) -> 0 | J6: =SUMIFS(P_violacea_Spain_Med!$J:$J, P_violacea_Spain_Med!$B:$B, ">="&DATE(2008,9,1), P_violacea_Spain_Med!$B:$B, "<="&DATE(2008,9,30)) -> 0 | K6: =SUMIFS(P_violacea_Spain_Med!$J:$J, P_violacea_Spain_Med!$B:$B, ">="&DATE(2008,10,1), P_violacea_Spain_Med!$B:$B, "<="&DATE(2008,10,31)) -> 0 | L6: =SUMIFS(P_violacea_Spain_Med!$J:$J, P_violacea_Spain_Med!$B:$B, ">="&DATE(2008,11,1), P_violacea_Spain_Med!$B:$B, "<="&DATE(2008,11,30)) -> 0 | M6: =SUMIFS(P_violacea_Spain_Med!$J:$J, P_violacea_Spain_Med!$B:$B, ">="&DATE(2008,12,1), P_violacea_Spain_Med!$B:$B, "<="&DATE(2008,12,31)) -> 0 | N6: =SUM($B6:$M6) -> 0
A7: 2009 | B7: =SUMIFS(P_violacea_Spain_Med!$J:$J, P_violacea_Spain_Med!$B:$B, ">="&DATE(2009,1,1), P_violacea_Spain_Med!$B:$B, "<="&DATE(2009,1,31)) -> 0 | C7: =SUMIFS(P_violacea_Spain_Med!$J:$J, P_violacea_Spain_Med!$B:$B, ">="&DATE(2009,2,1), P_violacea_Spain_Med!$B:$B, "<="&DATE(2009,2,28)) -> 0 | D7: =SUMIFS(P_violacea_Spain_Med!$J:$J, P_violacea_Spain_Med!$B:$B, ">="&DATE(2009,3,1), P_violacea_Spain_Med!$B:$B, "<="&DATE(2009,3,31)) -> 0 | E7: =SUMIFS(P_violacea_Spain_Med!$J:$J, P_violacea_Spain_Med!$B:$B, ">="&DATE(2009,4,1), P_violacea_Spain_Med!$B:$B, "<="&DATE(2009,4,30)) -> 0 | F7: =SUMIFS(P_violacea_Spain_Med!$J:$J, P_violacea_Spain_Med!$B:$B, ">="&DATE(2009,5,1), P_violacea_Spain_Med!$B:$B, "<="&DATE(2009,5,31)) -> 0 | G7: =SUMIFS(P_violacea_Spain_Med!$J:$J, P_violacea_Spain_Med!$B:$B, ">="&DATE(2009,6,1), P_violacea_Spain_Med!$B:$B, "<="&DATE(2009,6,30)) -> 0 | H7: =SUMIFS(P_violacea_Spain_Med!$J:$J, P_violacea_Spain_Med!$B:$B, ">="&DATE(2009,7,1), P_violacea_Spain_Med!$B:$B, "<="&DATE(2009,7,31)) -> 0 | I7: =SUMIFS(P_violacea_Spain_Med!$J:$J, P_violacea_Spain_Med!$B:$B, ">="&DATE(2009,8,1), P_violacea_Spain_Med!$B:$B, "<="&DATE(2009,8,31)) -> 0 | J7: =SUMIFS(P_violacea_Spain_Med!$J:$J, P_violacea_Spain_Med!$B:$B, ">="&DATE(2009,9,1), P_violacea_Spain_Med!$B:$B, "<="&DATE(2009,9,30)) -> 0 | K7: =SUMIFS(P_violacea_Spain_Med!$J:$J, P_violacea_Spain_Med!$B:$B, ">="&DATE(2009,10,1), P_violacea_Spain_Med!$B:$B, "<="&DATE(2009,10,31)) -> 0 | L7: =SUMIFS(P_violacea_Spain_Med!$J:$J, P_violacea_Spain_Med!$B:$B, ">="&DATE(2009,11,1), P_violacea_Spain_Med!$B:$B, "<="&DATE(2009,11,30)) -> 0 | M7: =SUMIFS(P_violacea_Spain_Med!$J:$J, P_violacea_Spain_Med!$B:$B, ">="&DATE(2009,12,1), P_violacea_Spain_Med!$B:$B, "<="&DATE(2009,12,31)) -> 0 | N7: =SUM($B7:$M7) -> 0
A8: 2010 | B8: =SUMIFS(P_violacea_Spain_Med!$J:$J, P_violacea_Spain_Med!$B:$B, ">="&DATE(2010,1,1), P_violacea_Spain_Med!$B:$B, "<="&DATE(2010,1,31)) -> 0 | C8: =SUMIFS(P_violacea_Spain_Med!$J:$J, P_violacea_Spain_Med!$B:$B, ">="&DATE(2010,2,1), P_violacea_Spain_Med!$B:$B, "<="&DATE(2010,2,28)) -> 0 | D8: =SUMIFS(P_violacea_Spain_Med!$J:$J, P_violacea_Spain_Med!$B:$B, ">="&DATE(2010,3,1), P_violacea_Spain_Med!$B:$B, "<="&DATE(2010,3,31)) -> 0 | E8: =SUMIFS(P_violacea_Spain_Med!$J:$J, P_violacea_Spain_Med!$B:$B, ">="&DATE(2010,4,1), P_violacea_Spain_Med!$B:$B, "<="&DATE(2010,4,30)) -> 0 | F8: =SUMIFS(P_violacea_Spain_Med!$J:$J, P_violacea_Spain_Med!$B:$B, ">="&DATE(2010,5,1), P_violacea_Spain_Med!$B:$B, "<="&DATE(2010,5,31)) -> 0 | G8: =SUMIFS(P_violacea_Spain_Med!$J:$J, P_violacea_Spain_Med!$B:$B, ">="&DATE(2010,6,1), P_violacea_Spain_Med!$B:$B, "<="&DATE(2010,6,30)) -> 0 | H8: =SUMIFS(P_violacea_Spain_Med!$J:$J, P_violacea_Spain_Med!$B:$B, ">="&DATE(2010,7,1), P_violacea_Spain_Med!$B:$B, "<="&DATE(2010,7,31)) -> 0 | I8: =SUMIFS(P_violacea_Spain_Med!$J:$J, P_violacea_Spain_Med!$B:$B, ">="&DATE(2010,8,1), P_violacea_Spain_Med!$B:$B, "<="&DATE(2010,8,31)) -> 0 | J8: =SUMIFS(P_violacea_Spain_Med!$J:$J, P_violacea_Spain_Med!$B:$B, ">="&DATE(2010,9,1), P_violacea_Spain_Med!$B:$B, "<="&DATE(2010,9,30)) -> 0 | K8: =SUMIFS(P_violacea_Spain_Med!$J:$J, P_violacea_Spain_Med!$B:$B, ">="&DATE(2010,10,1), P_violacea_Spain_Med!$B:$B, "<="&DATE(2010,10,31)) -> 0 | L8: =SUMIFS(P_violacea_Spain_Med!$J:$J, P_violacea_Spain_Med!$B:$B, ">="&DATE(2010,11,1), P_violacea_Spain_Med!$B:$B, "<="&DATE(2010,11,30)) -> 0 | M8: =SUMIFS(P_violacea_Spain_Med!$J:$J, P_violacea_Spain_Med!$B:$B, ">="&DATE(2010,12,1), P_violacea_Spain_Med!$B:$B, "<="&DATE(2010,12,31)) -> 0 | N8: =SUM($B8:$M8) -> 0
